<?xml version="1.0" ?>
<!-- =================================================================================== -->
<!-- |    This document was autogenerated by xacro from A02H-D.urdf.xacro              | -->
<!-- |    EDITING THIS FILE BY HAND IS NOT RECOMMENDED                                 | -->
<!-- =================================================================================== -->
<robot name="A02H-D">
  <!-- JOINTS-->
  <joint name="joint1" type="revolute">
    <parent link="base_link"/>
    <child link="link1"/>
    <origin rpy="0 0 3.141592653589793" xyz="0.0 0.0 0.175"/>
    <axis xyz="0 0 1"/>
    <limit effort="261" lower="-2.7925" upper="2.7925" velocity="1.7453"/>
    <safety_controller k_position="100.0" k_velocity="40.0" soft_lower_limit="-2.7925" soft_upper_limit="2.7925"/>
    <flexiv>
      <mdh_to_rca_coordinate_transform>
        <offset>0</offset>
        <direction>1</direction>
      </mdh_to_rca_coordinate_transform>
    </flexiv>
  </joint>
  <joint name="joint2" type="revolute">
    <parent link="link1"/>
    <child link="link2"/>
    <origin rpy="0 0 0" xyz="0.0 0.045 0.240"/>
    <axis xyz="0 1 0"/>
    <limit effort="261" lower="-2.2515" upper="2.2515" velocity="1.7453"/>
    <safety_controller k_position="100.0" k_velocity="40.0" soft_lower_limit="-2.2515" soft_upper_limit="2.2515"/>
    <flexiv>
      <mdh_to_rca_coordinate_transform>
        <offset>0</offset>
        <direction>1</direction>
      </mdh_to_rca_coordinate_transform>
    </flexiv>
  </joint>
  <joint name="joint3" type="revolute">
    <parent link="link2"/>
    <child link="link3"/>
    <origin rpy="0 0 0" xyz="0.0 0.050 0.215"/>
    <axis xyz="0 0 1"/>
    <limit effort="123" lower="-2.7925" upper="2.7925" velocity="2.0944"/>
    <safety_controller k_position="100.0" k_velocity="40.0" soft_lower_limit="-2.7925" soft_upper_limit="2.7925"/>
    <flexiv>
      <mdh_to_rca_coordinate_transform>
        <offset>0</offset>
        <direction>1</direction>
      </mdh_to_rca_coordinate_transform>
    </flexiv>
  </joint>
  <joint name="joint4" type="revolute">
    <parent link="link3"/>
    <child link="link4"/>
    <origin rpy="0 0 -3.141592653589793" xyz="-0.02 -0.045 0.20"/>
    <axis xyz="0 1 0"/>
    <limit effort="123" lower="-2.0071" upper="2.7053" velocity="2.0944"/>
    <safety_controller k_position="100.0" k_velocity="40.0" soft_lower_limit="-2.0071" soft_upper_limit="2.7053"/>
    <flexiv>
      <mdh_to_rca_coordinate_transform>
        <offset>0</offset>
        <direction>1</direction>
      </mdh_to_rca_coordinate_transform>
    </flexiv>
  </joint>
  <joint name="joint5" type="revolute">
    <parent link="link4"/>
    <child link="link5"/>
    <origin rpy="0 0 -3.141592653589793" xyz="-0.02 0.0426 0.205"/>
    <axis xyz="0 0 1"/>
    <limit effort="57" lower="-2.9671" upper="2.9671" velocity="3.8397"/>
    <safety_controller k_position="100.0" k_velocity="40.0" soft_lower_limit="-2.9671" soft_upper_limit="2.9671"/>
    <flexiv>
      <mdh_to_rca_coordinate_transform>
        <offset>0</offset>
        <direction>1</direction>
      </mdh_to_rca_coordinate_transform>
    </flexiv>
  </joint>
  <joint name="joint6" type="revolute">
    <parent link="link5"/>
    <child link="link6"/>
    <origin rpy="0 0 0" xyz="0.0 0.03 0.19"/>
    <axis xyz="0 1 0"/>
    <limit effort="57" lower="-1.3963" upper="4.5379" velocity="3.8397"/>
    <safety_controller k_position="100.0" k_velocity="40.0" soft_lower_limit="-1.3963" soft_upper_limit="4.5379"/>
    <flexiv>
      <mdh_to_rca_coordinate_transform>
        <offset>-1.5707963267948966</offset>
        <direction>1</direction>
      </mdh_to_rca_coordinate_transform>
    </flexiv>
  </joint>
  <joint name="joint7" type="revolute">
    <parent link="link6"/>
    <child link="link7"/>
    <origin rpy="0 -1.5707963267948966 0" xyz="-0.055 0.070 0.11"/>
    <axis xyz="0 0 1"/>
    <limit effort="57" lower="-2.9671" upper="2.9671" velocity="3.8397"/>
    <safety_controller k_position="100.0" k_velocity="40.0" soft_lower_limit="-2.9671" soft_upper_limit="2.9671"/>
    <flexiv>
      <mdh_to_rca_coordinate_transform>
        <offset>0</offset>
        <direction>1</direction>
      </mdh_to_rca_coordinate_transform>
    </flexiv>
  </joint>
  <joint name="link7_to_flange" type="fixed">
    <parent link="link7"/>
    <child link="flange"/>
    <origin rpy="0 0 -3.141592653589793" xyz="0.0 0.0 0.081"/>
  </joint>
  <!-- LINKS -->
  <link name="base_link">
    <inertial>
      <mass value="7.608"/>
      <origin rpy="0 0 0" xyz="0.0003 -0.0010 0.1178"/>
      <inertia ixx="0.0545" ixy="0" ixz="-0.0002" iyy="0.0549" iyz="0.0006" izz="0.0290"/>
    </inertial>
    <visual>
      <origin rpy="0 0 0" xyz="0 0 0"/>
      <geometry>
        <mesh filename="package://flexiv_description/meshes/A02L-M/visual/link0.obj"/>
      </geometry>
    </visual>
    <collision>
      <origin rpy="0 0 0" xyz="0 0 0"/>
      <geometry>
        <mesh filename="package://flexiv_description/meshes/A02L-M/collision/link0.obj"/>
      </geometry>
    </collision>
  </link>
  <link name="link1">
    <inertial>
      <mass value="7.946"/>
      <origin rpy="0 0 0" xyz="0.0001 0.0184 0.1821"/>
      <inertia ixx="0.0796" ixy="-0.0001" ixz="0.0001" iyy="0.0751" iyz="0.0093" izz="0.0288"/>
    </inertial>
    <visual>
      <origin rpy="0 0 0" xyz="0 0 0"/>
      <geometry>
        <mesh filename="package://flexiv_description/meshes/A02L-M/visual/link1.obj"/>
      </geometry>
    </visual>
    <collision>
      <origin rpy="0 0 0" xyz="0 0 0"/>
      <geometry>
        <mesh filename="package://flexiv_description/meshes/A02L-M/collision/link1.obj"/>
      </geometry>
    </collision>
  </link>
  <link name="link2">
    <inertial>
      <mass value="4.757"/>
      <origin rpy="0 0 0" xyz="0.0002 0.0509 0.1"/>
      <inertia ixx="0.0508" ixy="0" ixz="0" iyy="0.0527" iyz="-0.0001" izz="0.0108"/>
    </inertial>
    <visual>
      <origin rpy="0 0 0" xyz="0 0 0"/>
      <geometry>
        <mesh filename="package://flexiv_description/meshes/A02L-M/visual/link2.obj"/>
      </geometry>
    </visual>
    <collision>
      <origin rpy="0 0 0" xyz="0 0 0"/>
      <geometry>
        <mesh filename="package://flexiv_description/meshes/A02L-M/collision/link2.obj"/>
      </geometry>
    </collision>
  </link>
  <link name="link3">
    <inertial>
      <mass value="3.854"/>
      <origin rpy="0 0 0" xyz="-0.0118 -0.0117 0.1453"/>
      <inertia ixx="0.0275" ixy="0.0005" ixz="-0.0025" iyy="0.0263" iyz="-0.0030" izz="0.0099"/>
    </inertial>
    <visual>
      <origin rpy="0 0 0" xyz="0 0 0"/>
      <geometry>
        <mesh filename="package://flexiv_description/meshes/A02L-M/visual/link3.obj"/>
      </geometry>
    </visual>
    <collision>
      <origin rpy="0 0 0" xyz="0 0 0"/>
      <geometry>
        <mesh filename="package://flexiv_description/meshes/A02L-M/collision/link3.obj"/>
      </geometry>
    </collision>
  </link>
  <link name="link4">
    <inertial>
      <mass value="2.936"/>
      <origin rpy="0 0 0" xyz="-0.0119 0.0443 0.0940"/>
      <inertia ixx="0.0257" ixy="0" ixz="-0.0022" iyy="0.0266" iyz="-0.0002" izz="0.0047"/>
    </inertial>
    <visual>
      <origin rpy="0 0 0" xyz="0 0 0"/>
      <geometry>
        <mesh filename="package://flexiv_description/meshes/A02L-M/visual/link4.obj"/>
      </geometry>
    </visual>
    <collision>
      <origin rpy="0 0 0" xyz="0 0 0"/>
      <geometry>
        <mesh filename="package://flexiv_description/meshes/A02L-M/collision/link4.obj"/>
      </geometry>
    </collision>
  </link>
  <link name="link5">
    <inertial>
      <mass value="2.349"/>
      <origin rpy="0 0 0" xyz="0.0002 0.0028 0.1336"/>
      <inertia ixx="0.0144" ixy="0" ixz="0" iyy="0.0137" iyz="0.0008" izz="0.0037"/>
    </inertial>
    <visual>
      <origin rpy="0 0 0" xyz="0 0 0"/>
      <geometry>
        <mesh filename="package://flexiv_description/meshes/A02L-M/visual/link5.obj"/>
      </geometry>
    </visual>
    <collision>
      <origin rpy="0 0 0" xyz="0 0 0"/>
      <geometry>
        <mesh filename="package://flexiv_description/meshes/A02L-M/collision/link5.obj"/>
      </geometry>
    </collision>
  </link>
  <link name="link6">
    <inertial>
      <mass value="2.101"/>
      <origin rpy="0 0 0" xyz="-0.0103 0.0563 0.0707"/>
      <inertia ixx="0.0081" ixy="-0.0003" ixz="-0.0009" iyy="0.0084" iyz="0.0017" izz="0.0035"/>
    </inertial>
    <visual>
      <origin rpy="0 0 0" xyz="0 0 0"/>
      <geometry>
        <mesh filename="package://flexiv_description/meshes/A02L-M/visual/link6.obj"/>
      </geometry>
    </visual>
    <collision>
      <origin rpy="0 0 0" xyz="0 0 0"/>
      <geometry>
        <mesh filename="package://flexiv_description/meshes/A02L-M/collision/link6.obj"/>
      </geometry>
    </collision>
  </link>
  <link name="link7">
    <inertial>
      <mass value="0.868"/>
      <origin rpy="0 0 0" xyz="0.0001 -0.0003 0.0286"/>
      <inertia ixx="0.0011" ixy="0" ixz="0" iyy="0.0011" iyz="0" izz="0.0010"/>
    </inertial>
    <visual>
      <origin rpy="0 0 0" xyz="0 0 0"/>
      <geometry>
        <mesh filename="package://flexiv_description/meshes/A02L-M/visual/link7.obj"/>
      </geometry>
    </visual>
    <collision>
      <origin rpy="0 0 0" xyz="0 0 0"/>
      <geometry>
        <mesh filename="package://flexiv_description/meshes/A02L-M/collision/link7.obj"/>
      </geometry>
    </collision>
  </link>
  <link name="flange"/>
  <material name="rizon_blue">
    <color rgba="0. 0. 1. 0.5"/>
  </material>
  <material name="rizon_light_grey">
    <color rgba="0.9 0.9 0.9 1"/>
  </material>
  <material name="rizon_dark_grey">
    <color rgba="0.2 0.2 0.2 1"/>
  </material>
  <material name="rizon_white">
    <color rgba="1 1 1 1"/>
  </material>
</robot>
